Workbook

Sheet As Cleaned
A1: DATE | B1: Airline code | C1: Flight Designator | D1: SOBT | E1: Hour | F1: Routing | G1: Traffic Type | H1: Public Terminal | I1: GHA | J1: Seats | K1: Pax | L1: D-4 Pax | M1: D-3 Pax | N1: D-2 Pax | O1: D-4 | P1: D-3 | Q1: D-2 | R1: Σ split = Pax? | S1: Pax = 80%·Seats?
A2: ='As Received'!A2 | B2: ='As Received'!B2 | C2: ='As Received'!C2 | D2: ='As Received'!D2 | E2: ='As Received'!E2 | F2: ='As Received'!F2 | G2: ='As Received'!G2 | H2: ='As Received'!H2 | ... Q2: ='As Received'!Q2 | R2: =IF(K2="","",K2-(L2+M2+N2)) | S2: =IF(J2="","",K2-ROUND(0.8*J2,0))
A3: ='As Received'!A3 | B3: ='As Received'!B3 | C3: ='As Received'!C3 | D3: ='As Received'!D3 | E3: ='As Received'!E3 | F3: ='As Received'!F3 | G3: ='As Received'!G3 | H3: ='As Received'!H3 | ... Q3: ='As Received'!Q3 | R3: =IF(K3="","",K3-(L3+M3+N3)) | S3: =IF(J3="","",K3-ROUND(0.8*J3,0))
A4: ='As Received'!A4 | B4: ='As Received'!B4 | C4: ='As Received'!C4 | D4: ='As Received'!D4 | E4: ='As Received'!E4 | F4: ='As Received'!F4 | G4: ='As Received'!G4 | H4: ='As Received'!H4 | ... Q4: ='As Received'!Q4 | R4: =IF(K4="","",K4-(L4+M4+N4)) | S4: =IF(J4="","",K4-ROUND(0.8*J4,0))
A5: ='As Received'!A5 | B5: ='As Received'!B5 | C5: ='As Received'!C5 | D5: ='As Received'!D5 | E5: ='As Received'!E5 | F5: ='As Received'!F5 | G5: ='As Received'!G5 | H5: ='As Received'!H5 | ... Q5: ='As Received'!Q5 | R5: =IF(K5="","",K5-(L5+M5+N5)) | S5: =IF(J5="","",K5-ROUND(0.8*J5,0))
A6: ='As Received'!A6 | B6: ='As Received'!B6 | C6: ='As Received'!C6 | D6: ='As Received'!D6 | E6: ='As Received'!E6 | F6: ='As Received'!F6 | G6: ='As Received'!G6 | H6: ='As Received'!H6 | ... Q6: ='As Received'!Q6 | R6: =IF(K6="","",K6-(L6+M6+N6)) | S6: =IF(J6="","",K6-ROUND(0.8*J6,0))
A7: ='As Received'!A7 | B7: ='As Received'!B7 | C7: ='As Received'!C7 | D7: ='As Received'!D7 | E7: ='As Received'!E7 | F7: ='As Received'!F7 | G7: ='As Received'!G7 | H7: ='As Received'!H7 | ... Q7: ='As Received'!Q7 | R7: =IF(K7="","",K7-(L7+M7+N7)) | S7: =IF(J7="","",K7-ROUND(0.8*J7,0))
A8: ='As Received'!A8 | B8: ='As Received'!B8 | C8: ='As Received'!C8 | D8: ='As Received'!D8 | E8: ='As Received'!E8 | F8: ='As Received'!F8 | G8: ='As Received'!G8 | H8: ='As Received'!H8 | ... Q8: ='As Received'!Q8 | R8: =IF(K8="","",K8-(L8+M8+N8)) | S8: =IF(J8="","",K8-ROUND(0.8*J8,0))
A9: ='As Received'!A9 | B9: ='As Received'!B9 | C9: ='As Received'!C9 | D9: ='As Received'!D9 | E9: ='As Received'!E9 | F9: ='As Received'!F9 | G9: ='As Received'!G9 | H9: ='As Received'!H9 | ... Q9: ='As Received'!Q9 | R9: =IF(K9="","",K9-(L9+M9+N9)) | S9: =IF(J9="","",K9-ROUND(0.8*J9,0))
A10: ='As Received'!A10 | B10: ='As Received'!B10 | C10: ='As Received'!C10 | D10: ='As Received'!D10 | E10: ='As Received'!E10 | F10: ='As Received'!F10 | G10: ='As Received'!G10 | H10: ='As Received'!H10 | ... Q10: ='As Received'!Q10 | R10: =IF(K10="","",K10-(L10+M10+N10)) | S10: =IF(J10="","",K10-ROUND(0.8*J10,0))
A11: ='As Received'!A11 | B11: ='As Received'!B11 | C11: ='As Received'!C11 | D11: ='As Received'!D11 | E11: ='As Received'!E11 | F11: ='As Received'!F11 | G11: ='As Received'!G11 | H11: ='As Received'!H11 | ... Q11: ='As Received'!Q11 | R11: =IF(K11="","",K11-(L11+M11+N11)) | S11: =IF(J11="","",K11-ROUND(0.8*J11,0))
A12: ='As Received'!A12 | B12: ='As Received'!B12 | C12: ='As Received'!C12 | D12: ='As Received'!D12 | E12: ='As Received'!E12 | F12: ='As Received'!F12 | G12: ='As Received'!G12 | H12: ='As Received'!H12 | ... Q12: ='As Received'!Q12 | R12: =IF(K12="","",K12-(L12+M12+N12)) | S12: =IF(J12="","",K12-ROUND(0.8*J12,0))
A13: ='As Received'!A13 | B13: ='As Received'!B13 | C13: ='As Received'!C13 | D13: ='As Received'!D13 | E13: ='As Received'!E13 | F13: ='As Received'!F13 | G13: ='As Received'!G13 | H13: ='As Received'!H13 | ... Q13: ='As Received'!Q13 | R13: =IF(K13="","",K13-(L13+M13+N13)) | S13: =IF(J13="","",K13-ROUND(0.8*J13,0))
... A166: ='As Received'!A166 | B166: ='As Received'!B166 | C166: ='As Received'!C166 | D166: ='As Received'!D166 | E166: ='As Received'!E166 | F166: ='As Received'!F166 | G166: ='As Received'!G166 | H166: ='As Received'!H166 | ... Q166: ='As Received'!Q166 | R166: =IF(K166="","",K166-(L166+M166+N166)) | S166: =IF(J166="","",K166-ROUND(0.8*J166,0))
C167: TOTAL | J167: =SUM(J2:J166) | K167: =SUM(K2:K166) | L167: =SUM(L2:L166) | M167: =SUM(M2:M166) | N167: =SUM(N2:N166)

Sheet As Received
A1: DATE | B1: Airline code | C1: Flight Designator | D1: SOBT | E1: Hour | F1: Routing | G1: Traffic Type | H1: Public Terminal | I1: GHA | J1: Seats | K1: Pax | L1: D-4 Pax | M1: D-3 Pax | N1: D-2 Pax | O1: D-4 | P1: D-3 | Q1: D-2
A2: 21-06-2026 | B2: AI | C2: AI 173 | D2: 36527.003 | E2: 0 | F2: DEL-CCU-SFO | G2: INTERNATIONAL | H2: Terminal 3 | I2: AISATS | J2: 288 | K2: 230 | L2: 69 | M2: 92 | N2: 69 | O2: 36526.837 | P2: 36526.878 | Q2: 36526.92
A3: 21-06-2026 | B3: AI | C3: AI 312 | D3: 36527.003 | E3: 0 | F3: DEL-ICN | G3: INTERNATIONAL | H3: Terminal 3 | I3: AISATS | J3: 259 | K3: 207 | L3: 62 | M3: 83 | N3: 62 | O3: 36526.837 | P3: 36526.878 | Q3: 36526.92
A4: 21-06-2026 | B4: VJ | C4: VJ 972 | D4: 36527.003 | E4: 0 | F4: DEL-HAN | G4: INTERNATIONAL | H4: Terminal 3 | I4: BFS | J4: 377 | K4: 302 | L4: 91 | M4: 121 | N4: 91 | O4: 36526.837 | P4: 36526.878 | Q4: 36526.92
A5: 21-06-2026 | B5: AI | C5: AI 187 | D5: 36527.007 | E5: 0 | F5: DEL-VIE-YYZ | G5: INTERNATIONAL | H5: Terminal 3 | I5: AISATS | J5: 328 | K5: 262 | L5: 79 | M5: 105 | N5: 79 | O5: 36526.84 | P5: 36526.882 | Q5: 36526.924
A6: 21-06-2026 | B6: AI | C6: AI 161 | D6: 36527.021 | E6: 0 | F6: DEL-LHR | G6: INTERNATIONAL | H6: Terminal 3 | I6: AISATS | J6: 316 | K6: 253 | L6: 76 | M6: 101 | N6: 76 | O6: 36526.854 | P6: 36526.896 | Q6: 36526.938
A7: 21-06-2026 | B7: AI | C7: AI 2336 | D7: 36527.021 | E7: 0 | F7: DEL-BKK | G7: INTERNATIONAL | H7: Terminal 3 | I7: AISATS | J7: 164 | K7: 131 | L7: 39 | M7: 52 | N7: 39 | O7: 36526.854 | P7: 36526.896 | Q7: 36526.938
A8: 21-06-2026 | B8: AI | C8: AI 2118 | D8: 36527.028 | E8: 0 | F8: DEL-SIN | G8: INTERNATIONAL | H8: Terminal 3 | I8: AISATS | J8: 188 | K8: 150 | L8: 45 | M8: 60 | N8: 45 | O8: 36526.861 | P8: 36526.903 | Q8: 36526.944
A9: 21-06-2026 | B9: AF | C9: AF 283 | D9: 36527.035 | E9: 0 | F9: DEL-CDG | G9: INTERNATIONAL | H9: Terminal 3 | I9: AISATS | J9: 188 | K9: 150 | L9: 45 | M9: 60 | N9: 45 | O9: 36526.868 | P9: 36526.91 | Q9: 36526.951
A10: 21-06-2026 | B10: AI | C10: AI 302 | D10: 36527.038 | E10: 0 | F10: DEL-SYD | G10: INTERNATIONAL | H10: Terminal 3 | I10: BFS | J10: 328 | K10: 262 | L10: 79 | M10: 105 | N10: 79 | O10: 36526.872 | P10: 36526.913 | Q10: 36526.955
A11: 21-06-2026 | B11: AI | C11: AI 277 | D11: 36527.042 | E11: 1 | F11: DEL-CMB | G11: INTERNATIONAL | H11: Terminal 3 | I11: AISATS | J11: 259 | K11: 207 | L11: 62 | M11: 83 | N11: 62 | O11: 36526.875 | P11: 36526.917 | Q11: 36526.958
A12: 21-06-2026 | B12: LX | C12: LX 147 | D12: 36527.045 | E12: 1 | F12: DEL-ZRH | G12: INTERNATIONAL | H12: Terminal 3 | I12: AISATS | J12: 182 | K12: 146 | L12: 44 | M12: 58 | N12: 44 | O12: 36526.878 | P12: 36526.92 | Q12: 36526.962
A13: 21-06-2026 | B13: CX | C13: CX 694 | D13: 36527.049 | E13: 1 | F13: DEL-HKG | G13: INTERNATIONAL | H13: Terminal 3 | I13: BFS | J13: 236 | K13: 189 | L13: 57 | M13: 76 | N13: 57 | O13: 36526.882 | P13: 36526.924 | Q13: 36526.965
... A87: 21-06-2026 | B87: KC | C87: KC 908 | D87: 36527.476 | E87: 11 | F87: DEL-ALA | G87: INTERNATIONAL | H87: Terminal 3 | I87: AISATS | J87: 445 | K87: 356 | L87: 107 | M87: 142 | N87: 107 | O87: 36527.309 | P87: 36527.351 | Q87: 36527.392
A88: 21-06-2026 | B88: VERIFY | C88: VERIFY (87) | G88: INTERNATIONAL | H88: Terminal 3
A89: 21-06-2026 | B89: VERIFY | C89: VERIFY (88) | G89: INTERNATIONAL | H89: Terminal 3
A90: 21-06-2026 | B90: VERIFY | C90: VERIFY (89) | G90: INTERNATIONAL | H90: Terminal 3
A91: 21-06-2026 | B91: VERIFY | C91: VERIFY (90) | G91: INTERNATIONAL | H91: Terminal 3
A92: 21-06-2026 | B92: TG | C92: TG 324 | D92: 36527.486 | E92: 11 | F92: DEL-BKK | G92: INTERNATIONAL | H92: Terminal 3 | I92: BFS | J92: 264 | K92: 211 | L92: 63 | M92: 84 | N92: 63 | O92: 36527.319 | P92: 36527.361 | Q92: 36527.403
A93: 21-06-2026 | B93: MS | C93: MS 974 | D93: 36527.5 | E93: 12 | F93: DEL-CAI | G93: INTERNATIONAL | H93: Terminal 3 | I93: BFS | J93: 142 | K93: 114 | L93: 34 | M93: 46 | N93: 34 | O93: 36527.333 | P93: 36527.375 | Q93: 36527.417
A94: 21-06-2026 | B94: AI | C94: AI 2017 | D94: 36527.503 | E94: 12 | F94: DEL-LHR | G94: INTERNATIONAL | H94: Terminal 3 | I94: AISATS | J94: 316 | K94: 253 | L94: 76 | M94: 101 | N94: 76 | O94: 36527.337 | P94: 36527.378 | Q94: 36527.42
A95: 21-06-2026 | B95: C6 | C95: C6 558 | D95: 36527.507 | E95: 12 | F95: DEL-TAS | G95: INTERNATIONAL | H95: Terminal 3 | I95: AISATS | J95: 180 | K95: 144 | L95: 43 | M95: 58 | N95: 43 | O95: 36527.34 | P95: 36527.382 | Q95: 36527.424
A96: 21-06-2026 | B96: AI | C96: AI 151 | D96: 36527.51 | E96: 12 | F96: DEL-ZRH | G96: INTERNATIONAL | H96: Terminal 3 | I96: AISATS | J96: 259 | K96: 207 | L96: 62 | M96: 83 | N96: 62 | O96: 36527.344 | P96: 36527.385 | Q96: 36527.427
A97: 21-06-2026 | B97: AI | C97: AI 157 | D97: 36527.51 | E97: 12 | F97: DEL-CPH | G97: INTERNATIONAL | H97: Terminal 3 | I97: AISATS | J97: 256 | K97: 205 | L97: 62 | M97: 82 | N97: 62 | O97: 36527.344 | P97: 36527.385 | Q97: 36527.427
A98: 21-06-2026 | B98: AI | C98: AI 2029 | D98: 36527.514 | E98: 12 | F98: DEL-FRA | G98: INTERNATIONAL | H98: Terminal 3 | I98: AISATS | J98: 259 | K98: 207 | L98: 62 | M98: 83 | N98: 62 | O98: 36527.347 | P98: 36527.389 | Q98: 36527.431
A99: 21-06-2026 | B99: AI | C99: AI 2362 | D99: 36527.517 | E99: 12 | F99: DEL-MNL | G99: INTERNATIONAL | H99: Terminal 3 | I99: AISATS | J99: 188 | K99: 150 | L99: 45 | M99: 60 | N99: 45 | O99: 36527.351 | P99: 36527.392 | Q99: 36527.434
A100: 21-06-2026 | B100: KB | C100: KB 201 | D100: 36527.521 | E100: 12 | F100: DEL-PBH | G100: INTERNATIONAL | H100: Terminal 3 | I100: BFS | J100: 118 | K100: 94 | L100: 28 | M100: 38 | N100: 28 | O100: 36527.354 | P100: 36527.396 | Q100: 36527.438
A101: 21-06-2026 | B101: 6E | C101: 6E 1103 | D101: 36527.524 | E101: 12 | F101: DEL-DAC | G101: INTERNATIONAL | H101: Terminal 3 | I101: IndiGo | J101: 232 | K101: 186 | L101: 56 | M101: 74 | N101: 56 | O101: 36527.358 | P101: 36527.399 | Q101: 36527.441
A102: 21-06-2026 | B102: AI | C102: AI 281 | D102: 36527.528 | E102: 12 | F102: DEL-CMB | G102: INTERNATIONAL | H102: Terminal 3 | I102: AISATS | J102: 182 | K102: 146 | L102: 44 | M102: 58 | N102: 44 | O102: 36527.361 | P102: 36527.403 | Q102: 36527.444
A103: 21-06-2026 | B103: AI | C103: AI 137 | D103: 36527.535 | E103: 12 | F103: DEL-MXP | G103: INTERNATIONAL | H103: Terminal 3 | I103: AISATS | J103: 259 | K103: 207 | L103: 62 | M103: 83 | N103: 62 | O103: 36527.368 | P103: 36527.41 | Q103: 36527.451
... A166: 21-06-2026 | B166: UA | C166: UA 083 | D166: 36527.983 | E166: 23 | F166: DEL-EWR | G166: INTERNATIONAL | H166: Terminal 3 | I166: AISATS | J166: 305 | K166: 244 | L166: 73 | M166: 98 | N166: 73 | O166: 36527.816 | P166: 36527.858 | Q166: 36527.899
C167: TOTAL | J167: =SUM(J2:J166) | K167: =SUM(K2:K166) | L167: =SUM(L2:L166) | M167: =SUM(M2:M166) | N167: =SUM(N2:N166)

Sheet GHA Assignment
A1: Airline Code | B1: GHA (majority) | C1: # Flights | D1: Mixed?
A2: 6E | B2: IndiGo | C2: 30 | D2: YES {'Ramp 360': 1, 'IndiGo': 23, 'AISATS': 5, 'BFS': 1}
A3: AA | B3: BFS | C3: 1
A4: AC | B4: AISATS | C4: 1
A5: AF | B5: AISATS | C5: 1
A6: AI | B6: AISATS | C6: 49 | D6: YES {'AISATS': 43, 'BFS': 4, 'Ramp 360': 2}
A7: AY | B7: IndiGo | C7: 1
A8: AZ | B8: AISATS | C8: 1
A9: B4 | B9: IndiGo | C9: 1
A10: BA | B10: Ramp 360 | C10: 2 | D10: YES {'Ramp 360': 1, 'AISATS': 1}
A11: C6 | B11: AISATS | C11: 1
A12: CA | B12: BFS | C12: 1
A13: CX | B13: BFS | C13: 2 | D13: YES {'BFS': 1, 'AISATS': 1}
A14: D7 | B14: AISATS | C14: 1
A15: EK | B15: AISATS | C15: 4 | D15: YES {'AISATS': 3, 'BFS': 1}
A16: ET | B16: BFS | C16: 2 | D16: YES {'BFS': 1, 'AISATS': 1}
A17: EY | B17: AISATS | C17: 3 | D17: YES {'AISATS': 2, 'IndiGo': 1}
A18: FG | B18: BFS | C18: 1
A19: FZ | B19: AISATS | C19: 1
A20: G9 | B20: BFS | C20: 2
A21: GF | B21: AISATS | C21: 2
A22: IA | B22: AISATS | C22: 1
A23: IX | B23: AISATS | C23: 3
A24: J2 | B24: Ramp 360 | C24: 1
A25: J9 | B25: IndiGo | C25: 1
A26: JL | B26: BFS | C26: 2
A27: K9 | B27: IndiGo | C27: 1
A28: KB | B28: BFS | C28: 1
A29: KC | B29: AISATS | C29: 2
... A32: KU | B32: BFS | C32: 2
A33: LH | B33: BFS | C33: 2 | D33: YES {'BFS': 1, 'IndiGo': 1}
A34: LO | B34: IndiGo | C34: 1
A35: LX | B35: AISATS | C35: 2 | D35: YES {'AISATS': 1, 'BFS': 1}
A36: MH | B36: AISATS | C36: 1
A37: MS | B37: BFS | C37: 1
A38: MU | B38: BFS | C38: 1
A39: NH | B39: AISATS | C39: 1
A40: OD | B40: IndiGo | C40: 1
A41: QR | B41: Ramp 360 | C41: 2
A42: RA | B42: BFS | C42: 1
...

Sheet Counter Times
A1: Flight # | B1: SOBT | C1: Counter Open (SOBT-4) | D1: Counter Close (SOBT-1)
A2: AI 173 | B2: 36527.003 | C2: 36526.837 | D2: 36526.962
A3: AI 312 | B3: 36527.003 | C3: 36526.837 | D3: 36526.962
A4: VJ 972 | B4: 36527.003 | C4: 36526.837 | D4: 36526.962
A5: AI 187 | B5: 36527.007 | C5: 36526.84 | D5: 36526.965
A6: AI 161 | B6: 36527.021 | C6: 36526.854 | D6: 36526.979
A7: AI 2336 | B7: 36527.021 | C7: 36526.854 | D7: 36526.979
A8: AI 2118 | B8: 36527.028 | C8: 36526.861 | D8: 36526.986
A9: AF 283 | B9: 36527.035 | C9: 36526.868 | D9: 36526.993
A10: AI 302 | B10: 36527.038 | C10: 36526.872 | D10: 36526.997
A11: AI 277 | B11: 36527.042 | C11: 36526.875 | D11: 36527
A12: LX 147 | B12: 36527.045 | C12: 36526.878 | D12: 36527.003
A13: CX 694 | B13: 36527.049 | C13: 36526.882 | D13: 36527.007
... A87: KC 908 | B87: 36527.476 | C87: 36527.309 | D87: 36527.434
A88: VERIFY (87)
A89: VERIFY (88)
A90: VERIFY (89)
A91: VERIFY (90)
A92: TG 324 | B92: 36527.486 | C92: 36527.319 | D92: 36527.444
A93: MS 974 | B93: 36527.5 | C93: 36527.333 | D93: 36527.458
A94: AI 2017 | B94: 36527.503 | C94: 36527.337 | D94: 36527.462
A95: C6 558 | B95: 36527.507 | C95: 36527.34 | D95: 36527.465
A96: AI 151 | B96: 36527.51 | C96: 36527.344 | D96: 36527.469
A97: AI 157 | B97: 36527.51 | C97: 36527.344 | D97: 36527.469
A98: AI 2029 | B98: 36527.514 | C98: 36527.347 | D98: 36527.472
A99: AI 2362 | B99: 36527.517 | C99: 36527.351 | D99: 36527.476
A100: KB 201 | B100: 36527.521 | C100: 36527.354 | D100: 36527.479
A101: 6E 1103 | B101: 36527.524 | C101: 36527.358 | D101: 36527.483
A102: AI 281 | B102: 36527.528 | C102: 36527.361 | D102: 36527.486
A103: AI 137 | B103: 36527.535 | C103: 36527.368 | D103: 36527.493
... A166: UA 083 | B166: 36527.983 | C166: 36527.816 | D166: 36527.941
